<sdf version='1.9'>
  <model name='asl_rover'>
    <pose>0 0 0 0 0 0</pose>
    <self_collide>false</self_collide>
    <static>false</static>
    <link name='base_link'>
      <pose>0 0 0 0 0 0</pose>
      <inertial>
        <pose>0 0 0 0 0 0</pose>
        <mass>1.5</mass>
        <inertia>
          <ixx>0.0073551250000000006</ixx>
          <ixy>0</ixy>
          <ixz>0</ixz>
          <iyy>0.02725</iyy>
          <iyz>0</iyz>
          <izz>0.033005125000000003</izz>
        </inertia>
      </inertial>
      <collision name='base_link_landing_pad_collision'>
        <pose>0 0 0.12 0 0 0</pose>
        <geometry>
          <box>
            <size>0.59999999999999998 0.59999999999999998 0.02</size>
          </box>
        </geometry>
        <surface>
          <contact>
            <ode>
              <min_depth>0.001</min_depth>
              <max_vel>0</max_vel>
            </ode>
          </contact>
          <friction>
            <ode/>
          </friction>
        </surface>
      </collision>
      <visual name='base_link_landing_pad_visual'>
        <pose>0 0 0.12 0 0 0</pose>
        <geometry>
          <box>
            <size>0.59999999999999998 0.59999999999999998 0.02</size>
          </box>
        </geometry>
        <material>
          <diffuse>1 1 1 1</diffuse>
          <specular>0.400000006 0.400000006 0.400000006 1</specular>
        </material>
        <surface>
          <contact>
            <ode>
              <min_depth>0.001</min_depth>
              <max_vel>0</max_vel>
            </ode>
          </contact>
          <friction>
            <ode/>
          </friction>
        </surface>
      </visual>
      <visual name='base_link_visual'>
        <pose>0 0 0 0 0 1.5707963267948963</pose>
        <geometry>
          <mesh filename="package://asl_rover_offboard/model/urdf/meshes/base.dae"/>
        </geometry>
        <material>
          <ambient>0.400000006 0.400000006 0.449999988 1</ambient>
          <diffuse>0.800000012 0.800000012 0.899999976 1</diffuse>
          <specular>1 1 1 1</specular>
          <emissive>0 0 0 1</emissive>
        </material>
      </visual>
      <gravity>true</gravity>
      <velocity_decay/>
      <sensor name='air_pressure_sensor' type='air_pressure'>
        <always_on>true</always_on>
        <update_rate>50</update_rate>
        <air_pressure>
          <pressure>
            <noise type='gaussian'>
              <mean>0</mean>
              <stddev>3</stddev>
            </noise>
          </pressure>
        </air_pressure>
      </sensor>
      <sensor name='magnetometer_sensor' type='magnetometer'>
        <always_on>true</always_on>
        <update_rate>100</update_rate>
        <magnetometer>
          <x>
            <noise type='gaussian'>
              <stddev>0.0001</stddev>
            </noise>
          </x>
          <y>
            <noise type='gaussian'>
              <stddev>0.0001</stddev>
            </noise>
          </y>
          <z>
            <noise type='gaussian'>
              <stddev>0.0001</stddev>
            </noise>
          </z>
        </magnetometer>
      </sensor>
      <sensor name='imu_sensor' type='imu'>
        <always_on>true</always_on>
        <update_rate>250</update_rate>
        <imu>
          <angular_velocity>
            <x>
              <noise type='gaussian'>
                <mean>0</mean>
                <stddev>0.00087266459999999998</stddev>
              </noise>
            </x>
            <y>
              <noise type='gaussian'>
                <mean>0</mean>
                <stddev>0.00087266459999999998</stddev>
              </noise>
            </y>
            <z>
              <noise type='gaussian'>
                <mean>0</mean>
                <stddev>0.00087266459999999998</stddev>
              </noise>
            </z>
          </angular_velocity>
          <linear_acceleration>
            <x>
              <noise type='gaussian'>
                <mean>0</mean>
                <stddev>0.0063699999999999998</stddev>
              </noise>
            </x>
            <y>
              <noise type='gaussian'>
                <mean>0</mean>
                <stddev>0.0063699999999999998</stddev>
              </noise>
            </y>
            <z>
              <noise type='gaussian'>
                <mean>0</mean>
                <stddev>0.0068599999999999998</stddev>
              </noise>
            </z>
          </linear_acceleration>
        </imu>
      </sensor>
      <sensor name='navsat_sensor' type='navsat'>
        <always_on>true</always_on>
        <update_rate>30</update_rate>
        <gps/>
      </sensor>
    </link>
    <joint name='wheel0_bar_base_joint' type='revolute'>
      <pose relative_to='base_link'>0.1925 0.12625 -0.0074999999999999997 -0.78539816339744839 0 0</pose>
      <child>wheel0_bar_link</child>
      <parent>base_link</parent>
      <axis>
        <xyz>1 0 0</xyz>
        <limit>
          <lower>-0</lower>
          <upper>0</upper>
        </limit>
        <dynamics>
          <spring_reference>0</spring_reference>
          <spring_stiffness>0</spring_stiffness>
          <damping>0</damping>
        </dynamics>
        <use_parent_model_frame>1</use_parent_model_frame>
      </axis>
    </joint>
    <link name='wheel0_bar_link'>
      <pose relative_to='wheel0_bar_base_joint'>0 0.059999999999999998 0 0 0 1.5707963267948963</pose>
      <inertial>
        <pose>0 0 0 0 0 0</pose>
        <mass>0.050000000000000003</mass>
        <inertia>
          <ixx>8.3333333333333333e-07</ixx>
          <ixy>0</ixy>
          <ixz>0</ixz>
          <iyy>6.041666666666666e-05</iyy>
          <iyz>0</iyz>
          <izz>6.041666666666666e-05</izz>
        </inertia>
      </inertial>
      <visual name='wheel0_bar1_visual'>
        <pose relative_to='wheel0_bar_link'>0 0.0275 0 0 0 0</pose>
        <geometry>
          <mesh filename="package://asl_rover_offboard/model/urdf/meshes/bar.dae"/>
        </geometry>
        <material>
          <ambient>0.400000006 0.400000006 0.449999988 1</ambient>
          <diffuse>0.800000012 0.800000012 0.899999976 1</diffuse>
          <specular>1 1 1 1</specular>
          <emissive>0 0 0 1</emissive>
        </material>
      </visual>
      <visual name='wheel0_bar2_visual'>
        <pose relative_to='wheel0_bar_link'>0 -0.0275 0 0 0 0</pose>
        <geometry>
          <mesh filename="package://asl_rover_offboard/model/urdf/meshes/bar.dae"/>
        </geometry>
        <material>
          <ambient>0.400000006 0.400000006 0.449999988 1</ambient>
          <diffuse>0.800000012 0.800000012 0.899999976 1</diffuse>
          <specular>1 1 1 1</specular>
          <emissive>0 0 0 1</emissive>
        </material>
      </visual>
      <visual name='wheel0_bar3_visual'>
        <pose relative_to='wheel0_bar_link'>0.018738329701443509 0.0275 -0.018738329701443509 0 0 0</pose>
        <geometry>
          <mesh filename="package://asl_rover_offboard/model/urdf/meshes/bar.dae"/>
        </geometry>
        <material>
          <ambient>0.400000006 0.400000006 0.449999988 1</ambient>
          <diffuse>0.800000012 0.800000012 0.899999976 1</diffuse>
          <specular>1 1 1 1</specular>
          <emissive>0 0 0 1</emissive>
        </material>
      </visual>
      <visual name='wheel0_bar4_visual'>
        <pose relative_to='wheel0_bar_link'>0.018738329701443509 -0.0275 -0.018738329701443509 0 0 0</pose>
        <geometry>
          <mesh filename="package://asl_rover_offboard/model/urdf/meshes/bar.dae"/>
        </geometry>
        <material>
          <ambient>0.400000006 0.400000006 0.449999988 1</ambient>
          <diffuse>0.800000012 0.800000012 0.899999976 1</diffuse>
          <specular>1 1 1 1</specular>
          <emissive>0 0 0 1</emissive>
        </material>
      </visual>
    </link>
    <joint name='wheel0_wheel_housing_bar_joint' type='revolute'>
      <pose relative_to='wheel0_bar_link'>0.059999999999999998 0 0 0.78539816339744828 0 -1.5707963267948966</pose>
      <child>wheel0_wheel_housing_link</child>
      <parent>wheel0_bar_link</parent>
      <axis>
        <xyz>1 0 0</xyz>
        <limit>
          <lower>-0</lower>
          <upper>0</upper>
        </limit>
        <dynamics>
          <spring_reference>0</spring_reference>
          <spring_stiffness>0</spring_stiffness>
        </dynamics>
        <use_parent_model_frame>1</use_parent_model_frame>
      </axis>
    </joint>
    <link name='wheel0_wheel_housing_link'>
      <pose relative_to='wheel0_wheel_housing_bar_joint'>0 0 -0.037499999999999999 0 0 0</pose>
      <inertial>
        <pose>0 0 0 0 0 0</pose>
        <mass>0.050000000000000003</mass>
        <inertia>
          <ixx>2.1733e-06</ixx>
          <ixy>0</ixy>
          <ixz>0</ixz>
          <iyy>2.1733e-06</iyy>
          <iyz>0</iyz>
          <izz>1.8e-07</izz>
        </inertia>
      </inertial>
      <visual name='wheel0_wheel_housing_visual'>
        <pose>0 0 0 0 0 1.5707963267948963</pose>
        <geometry>
          <mesh filename="package://asl_rover_offboard/model/urdf/meshes/wheel_housing.dae"/>
        </geometry>
        <material>
          <ambient>0.5 0.100000001 0 1</ambient>
          <diffuse>1 0.200000003 0 1</diffuse>
          <specular>0.800000012 0.300000012 0.200000003 1</specular>
          <emissive>0 0 0 1</emissive>
        </material>
      </visual>
    </link>
    <joint name='wheel0_wheel_joint' type='revolute'>
      <pose relative_to='wheel0_wheel_housing_link'>0 0.055 0 0 0 0</pose>
      <child>wheel0_link</child>
      <parent>wheel0_wheel_housing_link</parent>
      <axis>
        <xyz>0 1 0</xyz>
        <limit>
          <lower>-10000000000000000</lower>
          <upper>10000000000000000</upper>
        </limit>
        <dynamics>
          <spring_reference>0</spring_reference>
          <spring_stiffness>0</spring_stiffness>
          <friction>0.001</friction>
          <damping>0</damping>
        </dynamics>
        <use_parent_model_frame>1</use_parent_model_frame>
      </axis>
    </joint>
    <link name='wheel0_link'>
      <pose relative_to='wheel0_wheel_joint'>0 0 0 0 0 0</pose>
      <inertial>
        <pose>0 0 0 0 0 0</pose>
        <mass>0.14999999999999999</mass>
        <inertia>
          <ixx>0.00017999999999999998</ixx>
          <ixy>0</ixy>
          <ixz>0</ixz>
          <iyy>0.00027</iyy>
          <iyz>0</iyz>
          <izz>0.00017999999999999998</izz>
        </inertia>
      </inertial>
      <visual name='wheel0_wheel_housing_visual'>
        <pose>0 0 0 1.5707963267948963 0 0</pose>
        <geometry>
          <cylinder>
            <length>0.059999999999999998</length>
            <radius>0.059999999999999998</radius>
          </cylinder>
        </geometry>
        <material>
          <ambient>0.5 0.100000001 0 1</ambient>
          <diffuse>1 0.200000003 0 1</diffuse>
          <specular>0.800000012 0.300000012 0.200000003 1</specular>
          <emissive>0 0 0 1</emissive>
        </material>
      </visual>
      <collision name='wheel0_link_collision'>
        <pose>0 0 0 1.5707963267948963 0 0</pose>
        <geometry>
          <cylinder>
            <length>0.059999999999999998</length>
            <radius>0.059999999999999998</radius>
          </cylinder>
        </geometry>
        <max_contacts>1</max_contacts>
        <surface>
          <friction>
            <torsional>
              <coefficient>0.25</coefficient>
              <use_patch_radius>true</use_patch_radius>
              <surface_radius>0.068599999999999994</surface_radius>
            </torsional>
            <ode>
              <mu>1</mu>
              <mu2>1</mu2>
              <fdir1>1 0 0</fdir1>
              <slip1>0</slip1>
              <slip2>0</slip2>
            </ode>
          </friction>
          <bounce>
            <restitution_coefficient>0.01</restitution_coefficient>
            <threshold>1000000</threshold>
          </bounce>
          <contact>
            <ode>
              <min_depth>0.001</min_depth>
              <max_vel>0</max_vel>
              <kp>1000000</kp>
              <kd>100</kd>
            </ode>
          </contact>
        </surface>
      </collision>
    </link>
    <plugin name='gz::sim::systems::JointController' filename='gz-sim-joint-controller-system'>
      <joint_name>wheel0_wheel_joint</joint_name>
      <sub_topic>command/motor_speed</sub_topic>
      <use_actuator_msg>true</use_actuator_msg>
      <actuator_number>1</actuator_number>
      <p_gain>10.0</p_gain>
    </plugin>
    <joint name='wheel1_bar_base_joint' type='revolute'>
      <pose relative_to='base_link'>0.1925 -0.12625 -0.0074999999999999997 -2.3561944901923448 0 0</pose>
      <child>wheel1_bar_link</child>
      <parent>base_link</parent>
      <axis>
        <xyz>1 0 0</xyz>
        <limit>
          <lower>-0</lower>
          <upper>0</upper>
        </limit>
        <dynamics>
          <spring_reference>0</spring_reference>
          <spring_stiffness>0</spring_stiffness>
          <damping>0</damping>
        </dynamics>
        <use_parent_model_frame>1</use_parent_model_frame>
      </axis>
    </joint>
    <link name='wheel1_bar_link'>
      <pose relative_to='wheel1_bar_base_joint'>0 0.059999999999999998 0 0 0 1.5707963267948963</pose>
      <inertial>
        <pose>0 0 0 0 0 0</pose>
        <mass>0.050000000000000003</mass>
        <inertia>
          <ixx>8.3333333333333333e-07</ixx>
          <ixy>0</ixy>
          <ixz>0</ixz>
          <iyy>6.041666666666666e-05</iyy>
          <iyz>0</iyz>
          <izz>6.041666666666666e-05</izz>
        </inertia>
      </inertial>
      <visual name='wheel1_bar1_visual'>
        <pose relative_to='wheel1_bar_link'>0 -0.0275 0 0 0 0</pose>
        <geometry>
          <mesh filename="package://asl_rover_offboard/model/urdf/meshes/bar.dae"/>
        </geometry>
        <material>
          <ambient>0.400000006 0.400000006 0.449999988 1</ambient>
          <diffuse>0.800000012 0.800000012 0.899999976 1</diffuse>
          <specular>1 1 1 1</specular>
          <emissive>0 0 0 1</emissive>
        </material>
      </visual>
      <visual name='wheel1_bar2_visual'>
        <pose relative_to='wheel1_bar_link'>0 0.0275 0 0 0 0</pose>
        <geometry>
          <mesh filename="package://asl_rover_offboard/model/urdf/meshes/bar.dae"/>
        </geometry>
        <material>
          <ambient>0.400000006 0.400000006 0.449999988 1</ambient>
          <diffuse>0.800000012 0.800000012 0.899999976 1</diffuse>
          <specular>1 1 1 1</specular>
          <emissive>0 0 0 1</emissive>
        </material>
      </visual>
      <visual name='wheel1_bar3_visual'>
        <pose relative_to='wheel1_bar_link'>0.018738329701443509 -0.0275 0.018738329701443509 0 0 0</pose>
        <geometry>
          <mesh filename="package://asl_rover_offboard/model/urdf/meshes/bar.dae"/>
        </geometry>
        <material>
          <ambient>0.400000006 0.400000006 0.449999988 1</ambient>
          <diffuse>0.800000012 0.800000012 0.899999976 1</diffuse>
          <specular>1 1 1 1</specular>
          <emissive>0 0 0 1</emissive>
        </material>
      </visual>
      <visual name='wheel1_bar4_visual'>
        <pose relative_to='wheel1_bar_link'>0.018738329701443509 0.0275 0.018738329701443509 0 0 0</pose>
        <geometry>
          <mesh filename="package://asl_rover_offboard/model/urdf/meshes/bar.dae"/>
        </geometry>
        <material>
          <ambient>0.400000006 0.400000006 0.449999988 1</ambient>
          <diffuse>0.800000012 0.800000012 0.899999976 1</diffuse>
          <specular>1 1 1 1</specular>
          <emissive>0 0 0 1</emissive>
        </material>
      </visual>
    </link>
    <joint name='wheel1_wheel_housing_bar_joint' type='revolute'>
      <pose relative_to='wheel1_bar_link'>0.059999999999999998 0 0 2.3561944901923448 0 -1.5707963267948963</pose>
      <child>wheel1_wheel_housing_link</child>
      <parent>wheel1_bar_link</parent>
      <axis>
        <xyz>1 0 0</xyz>
        <limit>
          <lower>-0</lower>
          <upper>0</upper>
        </limit>
        <dynamics>
          <spring_reference>0</spring_reference>
          <spring_stiffness>0</spring_stiffness>
        </dynamics>
        <use_parent_model_frame>1</use_parent_model_frame>
      </axis>
    </joint>
    <link name='wheel1_wheel_housing_link'>
      <pose relative_to='wheel1_wheel_housing_bar_joint'>0 0 -0.037499999999999999 0 0 0</pose>
      <inertial>
        <pose>0 0 0 0 0 0</pose>
        <mass>0.050000000000000003</mass>
        <inertia>
          <ixx>2.1733e-06</ixx>
          <ixy>0</ixy>
          <ixz>0</ixz>
          <iyy>2.1733e-06</iyy>
          <iyz>0</iyz>
          <izz>1.8e-07</izz>
        </inertia>
      </inertial>
      <visual name='wheel1_wheel_housing_visual'>
        <pose>0 0 0 0 0 -1.5707963267948963</pose>
        <geometry>
          <mesh filename="package://asl_rover_offboard/model/urdf/meshes/wheel_housing.dae"/>
        </geometry>
        <material>
          <ambient>0.5 0.100000001 0 1</ambient>
          <diffuse>1 0.200000003 0 1</diffuse>
          <specular>0.800000012 0.300000012 0.200000003 1</specular>
          <emissive>0 0 0 1</emissive>
        </material>
      </visual>
    </link>
    <joint name='wheel1_wheel_joint' type='revolute'>
      <pose relative_to='wheel1_wheel_housing_link'>0 -0.055 0 0 0 0</pose>
      <child>wheel1_link</child>
      <parent>wheel1_wheel_housing_link</parent>
      <axis>
        <xyz>0 1 0</xyz>
        <limit>
          <lower>-10000000000000000</lower>
          <upper>10000000000000000</upper>
        </limit>
        <dynamics>
          <spring_reference>0</spring_reference>
          <spring_stiffness>0</spring_stiffness>
          <friction>0.001</friction>
          <damping>0</damping>
        </dynamics>
        <use_parent_model_frame>1</use_parent_model_frame>
      </axis>
    </joint>
    <link name='wheel1_link'>
      <pose relative_to='wheel1_wheel_joint'>0 0 0 0 0 0</pose>
      <inertial>
        <pose>0 0 0 0 0 0</pose>
        <mass>0.14999999999999999</mass>
        <inertia>
          <ixx>0.00017999999999999998</ixx>
          <ixy>0</ixy>
          <ixz>0</ixz>
          <iyy>0.00027</iyy>
          <iyz>0</iyz>
          <izz>0.00017999999999999998</izz>
        </inertia>
      </inertial>
      <visual name='wheel1_wheel_housing_visual'>
        <pose>0 0 0 1.5707963267948963 0 0</pose>
        <geometry>
          <cylinder>
            <length>0.059999999999999998</length>
            <radius>0.059999999999999998</radius>
          </cylinder>
        </geometry>
        <material>
          <ambient>0.5 0.100000001 0 1</ambient>
          <diffuse>1 0.200000003 0 1</diffuse>
          <specular>0.800000012 0.300000012 0.200000003 1</specular>
          <emissive>0 0 0 1</emissive>
        </material>
      </visual>
      <collision name='wheel1_link_collision'>
        <pose>0 0 0 1.5707963267948963 0 0</pose>
        <geometry>
          <cylinder>
            <length>0.059999999999999998</length>
            <radius>0.059999999999999998</radius>
          </cylinder>
        </geometry>
        <max_contacts>1</max_contacts>
        <surface>
          <friction>
            <torsional>
              <coefficient>0.25</coefficient>
              <use_patch_radius>true</use_patch_radius>
              <surface_radius>0.068599999999999994</surface_radius>
            </torsional>
            <ode>
              <mu>1</mu>
              <mu2>1</mu2>
              <fdir1>1 0 0</fdir1>
              <slip1>0</slip1>
              <slip2>0</slip2>
            </ode>
          </friction>
          <bounce>
            <restitution_coefficient>0.01</restitution_coefficient>
            <threshold>1000000</threshold>
          </bounce>
          <contact>
            <ode>
              <min_depth>0.001</min_depth>
              <max_vel>0</max_vel>
              <kp>1000000</kp>
              <kd>100</kd>
            </ode>
          </contact>
        </surface>
      </collision>
    </link>
    <plugin name='gz::sim::systems::JointController' filename='gz-sim-joint-controller-system'>
      <joint_name>wheel1_wheel_joint</joint_name>
      <sub_topic>command/motor_speed</sub_topic>
      <use_actuator_msg>true</use_actuator_msg>
      <actuator_number>0</actuator_number>
      <p_gain>10.0</p_gain>
    </plugin>
    <joint name='wheel2_bar_base_joint' type='revolute'>
      <pose relative_to='base_link'>-0.1925 0.12625 -0.0074999999999999997 -0.78539816339744839 0 0</pose>
      <child>wheel2_bar_link</child>
      <parent>base_link</parent>
      <axis>
        <xyz>1 0 0</xyz>
        <limit>
          <lower>-0</lower>
          <upper>0</upper>
        </limit>
        <dynamics>
          <spring_reference>0</spring_reference>
          <spring_stiffness>0</spring_stiffness>
          <damping>0</damping>
        </dynamics>
        <use_parent_model_frame>1</use_parent_model_frame>
      </axis>
    </joint>
    <link name='wheel2_bar_link'>
      <pose relative_to='wheel2_bar_base_joint'>0 0.059999999999999998 0 0 0 1.5707963267948963</pose>
      <inertial>
        <pose>0 0 0 0 0 0</pose>
        <mass>0.050000000000000003</mass>
        <inertia>
          <ixx>8.3333333333333333e-07</ixx>
          <ixy>0</ixy>
          <ixz>0</ixz>
          <iyy>6.041666666666666e-05</iyy>
          <iyz>0</iyz>
          <izz>6.041666666666666e-05</izz>
        </inertia>
      </inertial>
      <visual name='wheel2_bar1_visual'>
        <pose relative_to='wheel2_bar_link'>0 0.0275 0 0 0 0</pose>
        <geometry>
          <mesh filename="package://asl_rover_offboard/model/urdf/meshes/bar.dae"/>
        </geometry>
        <material>
          <ambient>0.400000006 0.400000006 0.449999988 1</ambient>
          <diffuse>0.800000012 0.800000012 0.899999976 1</diffuse>
          <specular>1 1 1 1</specular>
          <emissive>0 0 0 1</emissive>
        </material>
      </visual>
      <visual name='wheel2_bar2_visual'>
        <pose relative_to='wheel2_bar_link'>0 -0.0275 0 0 0 0</pose>
        <geometry>
          <mesh filename="package://asl_rover_offboard/model/urdf/meshes/bar.dae"/>
        </geometry>
        <material>
          <ambient>0.400000006 0.400000006 0.449999988 1</ambient>
          <diffuse>0.800000012 0.800000012 0.899999976 1</diffuse>
          <specular>1 1 1 1</specular>
          <emissive>0 0 0 1</emissive>
        </material>
      </visual>
      <visual name='wheel2_bar3_visual'>
        <pose relative_to='wheel2_bar_link'>0.018738329701443509 0.0275 -0.018738329701443509 0 0 0</pose>
        <geometry>
          <mesh filename="package://asl_rover_offboard/model/urdf/meshes/bar.dae"/>
        </geometry>
        <material>
          <ambient>0.400000006 0.400000006 0.449999988 1</ambient>
          <diffuse>0.800000012 0.800000012 0.899999976 1</diffuse>
          <specular>1 1 1 1</specular>
          <emissive>0 0 0 1</emissive>
        </material>
      </visual>
      <visual name='wheel2_bar4_visual'>
        <pose relative_to='wheel2_bar_link'>0.018738329701443509 -0.0275 -0.018738329701443509 0 0 0</pose>
        <geometry>
          <mesh filename="package://asl_rover_offboard/model/urdf/meshes/bar.dae"/>
        </geometry>
        <material>
          <ambient>0.400000006 0.400000006 0.449999988 1</ambient>
          <diffuse>0.800000012 0.800000012 0.899999976 1</diffuse>
          <specular>1 1 1 1</specular>
          <emissive>0 0 0 1</emissive>
        </material>
      </visual>
    </link>
    <joint name='wheel2_wheel_housing_bar_joint' type='revolute'>
      <pose relative_to='wheel2_bar_link'>0.059999999999999998 0 0 0.78539816339744828 0 -1.5707963267948966</pose>
      <child>wheel2_wheel_housing_link</child>
      <parent>wheel2_bar_link</parent>
      <axis>
        <xyz>1 0 0</xyz>
        <limit>
          <lower>-0</lower>
          <upper>0</upper>
        </limit>
        <dynamics>
          <spring_reference>0</spring_reference>
          <spring_stiffness>0</spring_stiffness>
        </dynamics>
        <use_parent_model_frame>1</use_parent_model_frame>
      </axis>
    </joint>
    <link name='wheel2_wheel_housing_link'>
      <pose relative_to='wheel2_wheel_housing_bar_joint'>0 0 -0.037499999999999999 0 0 0</pose>
      <inertial>
        <pose>0 0 0 0 0 0</pose>
        <mass>0.050000000000000003</mass>
        <inertia>
          <ixx>2.1733e-06</ixx>
          <ixy>0</ixy>
          <ixz>0</ixz>
          <iyy>2.1733e-06</iyy>
          <iyz>0</iyz>
          <izz>1.8e-07</izz>
        </inertia>
      </inertial>
      <visual name='wheel2_wheel_housing_visual'>
        <pose>0 0 0 0 0 1.5707963267948963</pose>
        <geometry>
          <mesh filename="package://asl_rover_offboard/model/urdf/meshes/wheel_housing.dae"/>
        </geometry>
        <material>
          <ambient>0.5 0.100000001 0 1</ambient>
          <diffuse>1 0.200000003 0 1</diffuse>
          <specular>0.800000012 0.300000012 0.200000003 1</specular>
          <emissive>0 0 0 1</emissive>
        </material>
      </visual>
    </link>
    <joint name='wheel2_wheel_joint' type='revolute'>
      <pose relative_to='wheel2_wheel_housing_link'>0 0.055 0 0 0 0</pose>
      <child>wheel2_link</child>
      <parent>wheel2_wheel_housing_link</parent>
      <axis>
        <xyz>0 1 0</xyz>
        <limit>
          <lower>-10000000000000000</lower>
          <upper>10000000000000000</upper>
        </limit>
        <dynamics>
          <spring_reference>0</spring_reference>
          <spring_stiffness>0</spring_stiffness>
          <friction>0.001</friction>
          <damping>0</damping>
        </dynamics>
        <use_parent_model_frame>1</use_parent_model_frame>
      </axis>
    </joint>
    <link name='wheel2_link'>
      <pose relative_to='wheel2_wheel_joint'>0 0 0 0 0 0</pose>
      <inertial>
        <pose>0 0 0 0 0 0</pose>
        <mass>0.14999999999999999</mass>
        <inertia>
          <ixx>0.00017999999999999998</ixx>
          <ixy>0</ixy>
          <ixz>0</ixz>
          <iyy>0.00027</iyy>
          <iyz>0</iyz>
          <izz>0.00017999999999999998</izz>
        </inertia>
      </inertial>
      <visual name='wheel2_wheel_housing_visual'>
        <pose>0 0 0 1.5707963267948963 0 0</pose>
        <geometry>
          <cylinder>
            <length>0.059999999999999998</length>
            <radius>0.059999999999999998</radius>
          </cylinder>
        </geometry>
        <material>
          <ambient>0.5 0.100000001 0 1</ambient>
          <diffuse>1 0.200000003 0 1</diffuse>
          <specular>0.800000012 0.300000012 0.200000003 1</specular>
          <emissive>0 0 0 1</emissive>
        </material>
      </visual>
      <collision name='wheel2_link_collision'>
        <pose>0 0 0 1.5707963267948963 0 0</pose>
        <geometry>
          <cylinder>
            <length>0.059999999999999998</length>
            <radius>0.059999999999999998</radius>
          </cylinder>
        </geometry>
        <max_contacts>1</max_contacts>
        <surface>
          <friction>
            <torsional>
              <coefficient>0.25</coefficient>
              <use_patch_radius>true</use_patch_radius>
              <surface_radius>0.068599999999999994</surface_radius>
            </torsional>
            <ode>
              <mu>1</mu>
              <mu2>1</mu2>
              <fdir1>1 0 0</fdir1>
              <slip1>0</slip1>
              <slip2>0</slip2>
            </ode>
          </friction>
          <bounce>
            <restitution_coefficient>0.01</restitution_coefficient>
            <threshold>1000000</threshold>
          </bounce>
          <contact>
            <ode>
              <min_depth>0.001</min_depth>
              <max_vel>0</max_vel>
              <kp>1000000</kp>
              <kd>100</kd>
            </ode>
          </contact>
        </surface>
      </collision>
    </link>
    <plugin name='gz::sim::systems::JointController' filename='gz-sim-joint-controller-system'>
      <joint_name>wheel2_wheel_joint</joint_name>
      <sub_topic>command/motor_speed</sub_topic>
      <use_actuator_msg>true</use_actuator_msg>
      <actuator_number>1</actuator_number>
      <p_gain>10.0</p_gain>
    </plugin>
    <joint name='wheel3_bar_base_joint' type='revolute'>
      <pose relative_to='base_link'>-0.1925 -0.12625 -0.0074999999999999997 -2.3561944901923448 0 0</pose>
      <child>wheel3_bar_link</child>
      <parent>base_link</parent>
      <axis>
        <xyz>1 0 0</xyz>
        <limit>
          <lower>-0</lower>
          <upper>0</upper>
        </limit>
        <dynamics>
          <spring_reference>0</spring_reference>
          <spring_stiffness>0</spring_stiffness>
          <damping>0</damping>
        </dynamics>
        <use_parent_model_frame>1</use_parent_model_frame>
      </axis>
    </joint>
    <link name='wheel3_bar_link'>
      <pose relative_to='wheel3_bar_base_joint'>0 0.059999999999999998 0 0 0 1.5707963267948963</pose>
      <inertial>
        <pose>0 0 0 0 0 0</pose>
        <mass>0.050000000000000003</mass>
        <inertia>
          <ixx>8.3333333333333333e-07</ixx>
          <ixy>0</ixy>
          <ixz>0</ixz>
          <iyy>6.041666666666666e-05</iyy>
          <iyz>0</iyz>
          <izz>6.041666666666666e-05</izz>
        </inertia>
      </inertial>
      <visual name='wheel3_bar1_visual'>
        <pose relative_to='wheel3_bar_link'>0 -0.0275 0 0 0 0</pose>
        <geometry>
          <mesh filename="package://asl_rover_offboard/model/urdf/meshes/bar.dae"/>
        </geometry>
        <material>
          <ambient>0.400000006 0.400000006 0.449999988 1</ambient>
          <diffuse>0.800000012 0.800000012 0.899999976 1</diffuse>
          <specular>1 1 1 1</specular>
          <emissive>0 0 0 1</emissive>
        </material>
      </visual>
      <visual name='wheel3_bar2_visual'>
        <pose relative_to='wheel3_bar_link'>0 0.0275 0 0 0 0</pose>
        <geometry>
          <mesh filename="package://asl_rover_offboard/model/urdf/meshes/bar.dae"/>
        </geometry>
        <material>
          <ambient>0.400000006 0.400000006 0.449999988 1</ambient>
          <diffuse>0.800000012 0.800000012 0.899999976 1</diffuse>
          <specular>1 1 1 1</specular>
          <emissive>0 0 0 1</emissive>
        </material>
      </visual>
      <visual name='wheel3_bar3_visual'>
        <pose relative_to='wheel3_bar_link'>0.018738329701443509 -0.0275 0.018738329701443509 0 0 0</pose>
        <geometry>
          <mesh filename="package://asl_rover_offboard/model/urdf/meshes/bar.dae"/>
        </geometry>
        <material>
          <ambient>0.400000006 0.400000006 0.449999988 1</ambient>
          <diffuse>0.800000012 0.800000012 0.899999976 1</diffuse>
          <specular>1 1 1 1</specular>
          <emissive>0 0 0 1</emissive>
        </material>
      </visual>
      <visual name='wheel3_bar4_visual'>
        <pose relative_to='wheel3_bar_link'>0.018738329701443509 0.0275 0.018738329701443509 0 0 0</pose>
        <geometry>
          <mesh filename="package://asl_rover_offboard/model/urdf/meshes/bar.dae"/>
        </geometry>
        <material>
          <ambient>0.400000006 0.400000006 0.449999988 1</ambient>
          <diffuse>0.800000012 0.800000012 0.899999976 1</diffuse>
          <specular>1 1 1 1</specular>
          <emissive>0 0 0 1</emissive>
        </material>
      </visual>
    </link>
    <joint name='wheel3_wheel_housing_bar_joint' type='revolute'>
      <pose relative_to='wheel3_bar_link'>0.059999999999999998 0 0 2.3561944901923448 0 -1.5707963267948963</pose>
      <child>wheel3_wheel_housing_link</child>
      <parent>wheel3_bar_link</parent>
      <axis>
        <xyz>1 0 0</xyz>
        <limit>
          <lower>-0</lower>
          <upper>0</upper>
        </limit>
        <dynamics>
          <spring_reference>0</spring_reference>
          <spring_stiffness>0</spring_stiffness>
        </dynamics>
        <use_parent_model_frame>1</use_parent_model_frame>
      </axis>
    </joint>
    <link name='wheel3_wheel_housing_link'>
      <pose relative_to='wheel3_wheel_housing_bar_joint'>0 0 -0.037499999999999999 0 0 0</pose>
      <inertial>
        <pose>0 0 0 0 0 0</pose>
        <mass>0.050000000000000003</mass>
        <inertia>
          <ixx>2.1733e-06</ixx>
          <ixy>0</ixy>
          <ixz>0</ixz>
          <iyy>2.1733e-06</iyy>
          <iyz>0</iyz>
          <izz>1.8e-07</izz>
        </inertia>
      </inertial>
      <visual name='wheel3_wheel_housing_visual'>
        <pose>0 0 0 0 0 -1.5707963267948963</pose>
        <geometry>
          <mesh filename="package://asl_rover_offboard/model/urdf/meshes/wheel_housing.dae"/>
        </geometry>
        <material>
          <ambient>0.5 0.100000001 0 1</ambient>
          <diffuse>1 0.200000003 0 1</diffuse>
          <specular>0.800000012 0.300000012 0.200000003 1</specular>
          <emissive>0 0 0 1</emissive>
        </material>
      </visual>
    </link>
    <joint name='wheel3_wheel_joint' type='revolute'>
      <pose relative_to='wheel3_wheel_housing_link'>0 -0.055 0 0 0 0</pose>
      <child>wheel3_link</child>
      <parent>wheel3_wheel_housing_link</parent>
      <axis>
        <xyz>0 1 0</xyz>
        <limit>
          <lower>-10000000000000000</lower>
          <upper>10000000000000000</upper>
        </limit>
        <dynamics>
          <spring_reference>0</spring_reference>
          <spring_stiffness>0</spring_stiffness>
          <friction>0.001</friction>
          <damping>0</damping>
        </dynamics>
        <use_parent_model_frame>1</use_parent_model_frame>
      </axis>
    </joint>
    <link name='wheel3_link'>
      <pose relative_to='wheel3_wheel_joint'>0 0 0 0 0 0</pose>
      <inertial>
        <pose>0 0 0 0 0 0</pose>
        <mass>0.14999999999999999</mass>
        <inertia>
          <ixx>0.00017999999999999998</ixx>
          <ixy>0</ixy>
          <ixz>0</ixz>
          <iyy>0.00027</iyy>
          <iyz>0</iyz>
          <izz>0.00017999999999999998</izz>
        </inertia>
      </inertial>
      <visual name='wheel3_wheel_housing_visual'>
        <pose>0 0 0 1.5707963267948963 0 0</pose>
        <geometry>
          <cylinder>
            <length>0.059999999999999998</length>
            <radius>0.059999999999999998</radius>
          </cylinder>
        </geometry>
        <material>
          <ambient>0.5 0.100000001 0 1</ambient>
          <diffuse>1 0.200000003 0 1</diffuse>
          <specular>0.800000012 0.300000012 0.200000003 1</specular>
          <emissive>0 0 0 1</emissive>
        </material>
      </visual>
      <collision name='wheel3_link_collision'>
        <pose>0 0 0 1.5707963267948963 0 0</pose>
        <geometry>
          <cylinder>
            <length>0.059999999999999998</length>
            <radius>0.059999999999999998</radius>
          </cylinder>
        </geometry>
        <max_contacts>1</max_contacts>
        <surface>
          <friction>
            <torsional>
              <coefficient>0.25</coefficient>
              <use_patch_radius>true</use_patch_radius>
              <surface_radius>0.068599999999999994</surface_radius>
            </torsional>
            <ode>
              <mu>1</mu>
              <mu2>1</mu2>
              <fdir1>1 0 0</fdir1>
              <slip1>0</slip1>
              <slip2>0</slip2>
            </ode>
          </friction>
          <bounce>
            <restitution_coefficient>0.01</restitution_coefficient>
            <threshold>1000000</threshold>
          </bounce>
          <contact>
            <ode>
              <min_depth>0.001</min_depth>
              <max_vel>0</max_vel>
              <kp>1000000</kp>
              <kd>100</kd>
            </ode>
          </contact>
        </surface>
      </collision>
    </link>
    <plugin name='gz::sim::systems::JointController' filename='gz-sim-joint-controller-system'>
      <joint_name>wheel3_wheel_joint</joint_name>
      <sub_topic>command/motor_speed</sub_topic>
      <use_actuator_msg>true</use_actuator_msg>
      <actuator_number>0</actuator_number>
      <p_gain>10.0</p_gain>
    </plugin>
    <link name='lidar_link'>
      <pose>0 0 0 0 0 0</pose>
      <inertial>
        <pose>0 0 0.043499999999999997 0 0 0</pose>
        <mass>0.37</mass>
        <inertia>
          <ixx>0.00034437749999999994</ixx>
          <ixy>0</ixy>
          <ixz>0</ixz>
          <iyy>0.00034437749999999994</iyy>
          <iyz>0</iyz>
          <izz>0.00022199999999999998</izz>
        </inertia>
      </inertial>
      <collision name='collision_base'>
        <pose>0 0 0.020500000000000001 0 0 0</pose>
        <geometry>
          <box>
            <size>0.059999999999999998 0.059999999999999998 0.041000000000000002</size>
          </box>
        </geometry>
      </collision>
      <collision name='collision_mid'>
        <pose>0 0 0.055 0 0 0</pose>
        <geometry>
          <cylinder>
            <radius>0.025000000000000001</radius>
            <length>0.028000000000000001</length>
          </cylinder>
        </geometry>
      </collision>
      <collision name='collision_top'>
        <pose>0 0 0.078 0 0 0</pose>
        <geometry>
          <box>
            <size>0.056000000000000001 0.056000000000000001 0.017999999999999999</size>
          </box>
        </geometry>
      </collision>
      <visual name='visual'>
        <geometry>
          <mesh filename="package://asl_rover_offboard/model/urdf/meshes/lidar_2d_v2.dae"/>
        </geometry>
      </visual>
      <sensor name='lidar_2d_v2' type='gpu_lidar'>
        <pose>0 0 0.055 0 0 0</pose>
        <ray>
          <scan>
            <horizontal>
              <resolution>1</resolution>
              <min_angle>-1.2</min_angle>
              <max_angle>1.2</max_angle>
              <samples>640</samples>
            </horizontal>
          </scan>
          <range>
            <min>0.14999999999999999</min>
            <max>12</max>
            <resolution>0.01</resolution>
          </range>
          <noise>
            <type>gaussian</type>
            <mean>0</mean>
            <stddev>0.001</stddev>
          </noise>
        </ray>
        <always_on>true</always_on>
        <update_rate>30</update_rate>
        <visualize>true</visualize>
      </sensor>
    </link>
    <joint name='lidar_model_joint' type='fixed'>
      <parent>base_link</parent>
      <child>lidar_link</child>
      <pose relative_to='base_link'>0.20000000000000001 0 0.050000000000000003 3.1415926535897931 0 0</pose>
    </joint>
    <plugin name='gz::sim::systems::JointStatePublisher' filename='gz-sim-joint-state-publisher-system'>
      <joint_name>wheel0_wheel_joint</joint_name>
      <joint_name>wheel1_wheel_joint</joint_name>
      <joint_name>wheel2_wheel_joint</joint_name>
      <joint_name>wheel3_wheel_joint</joint_name>
    </plugin>
  </model>
</sdf>
